Exception in thread Thread-1:
Traceback (most recent call last):
  File "/usr/local/lib/python3.7/threading.py", line 917, in _bootstrap_inner
    self.run()
  File "/usr/local/lib/python3.7/threading.py", line 865, in run
    self._target(*self._args, **self._kwargs)
  File "app.py", line 58, in _kubernetes_job
    _read_work(**kwargs)
  File "app.py", line 103, in _read_work
    simple_http_client_get.perform(line_number=line_number)
  File "/app/models/simple_http_log_client.py", line 26, in perform
    return self._simple_requests_scenario(line_number)
  File "/app/models/simple_http_log_client.py", line 31, in _simple_requests_scenario
    return self.session.get(f"{self.api_url}/line/{line_number}")
  File "/usr/local/lib/python3.7/site-packages/requests/sessions.py", line 542, in get
    return self.request('GET', url, **kwargs)
  File "/usr/local/lib/python3.7/site-packages/requests/sessions.py", line 515, in request
    prep = self.prepare_request(req)
  File "/usr/local/lib/python3.7/site-packages/requests/sessions.py", line 453, in prepare_request
    hooks=merge_hooks(request.hooks, self.hooks),
  File "/usr/local/lib/python3.7/site-packages/requests/models.py", line 318, in prepare
    self.prepare_url(url, params)
  File "/usr/local/lib/python3.7/site-packages/requests/models.py", line 395, in prepare_url
    raise InvalidURL("Invalid URL %r: No host supplied" % url)
requests.exceptions.InvalidURL: Invalid URL 'http://:8000/line/913559': No host supplied

Exception in thread 1:
Traceback (most recent call last):
  File "/usr/local/lib/python3.7/threading.py", line 917, in _bootstrap_inner
    self.run()
  File "/usr/local/lib/python3.7/threading.py", line 865, in run
    self._target(*self._args, **self._kwargs)
  File "app.py", line 58, in _kubernetes_job
    _read_work(**kwargs)
  File "app.py", line 100, in _read_work
    calculate_latency_time_between_get_request(simple_http_client_get, line_number)
  File "app.py", line 108, in calculate_latency_time_between_get_request
    simple_http_client_get.perform(line_number=line_number)
  File "/app/models/simple_http_log_client.py", line 26, in perform
    return self._simple_requests_scenario(line_number)
  File "/app/models/simple_http_log_client.py", line 31, in _simple_requests_scenario
    return self.session.get(f"{self.api_url}/line/{line_number}")
  File "/usr/local/lib/python3.7/site-packages/requests/sessions.py", line 542, in get
    return self.request('GET', url, **kwargs)
  File "/usr/local/lib/python3.7/site-packages/requests/sessions.py", line 515, in request
    prep = self.prepare_request(req)
  File "/usr/local/lib/python3.7/site-packages/requests/sessions.py", line 453, in prepare_request
    hooks=merge_hooks(request.hooks, self.hooks),
  File "/usr/local/lib/python3.7/site-packages/requests/models.py", line 318, in prepare
    self.prepare_url(url, params)
  File "/usr/local/lib/python3.7/site-packages/requests/models.py", line 395, in prepare_url
    raise InvalidURL("Invalid URL %r: No host supplied" % url)
requests.exceptions.InvalidURL: Invalid URL 'http://:8000/line/921591': No host supplied

Exception in thread 2:
Traceback (most recent call last):
  File "/usr/local/lib/python3.7/threading.py", line 917, in _bootstrap_inner
    self.run()
  File "/usr/local/lib/python3.7/threading.py", line 865, in run
    self._target(*self._args, **self._kwargs)
  File "app.py", line 58, in _kubernetes_job
    _read_work(**kwargs)
  File "app.py", line 103, in _read_work
    simple_http_client_get.perform(line_number=line_number)
  File "/app/models/simple_http_log_client.py", line 26, in perform
    return self._simple_requests_scenario(line_number)
  File "/app/models/simple_http_log_client.py", line 31, in _simple_requests_scenario
    return self.session.get(f"{self.api_url}/line/{line_number}")
  File "/usr/local/lib/python3.7/site-packages/requests/sessions.py", line 542, in get
    return self.request('GET', url, **kwargs)
  File "/usr/local/lib/python3.7/site-packages/requests/sessions.py", line 515, in request
    prep = self.prepare_request(req)
  File "/usr/local/lib/python3.7/site-packages/requests/sessions.py", line 453, in prepare_request
    hooks=merge_hooks(request.hooks, self.hooks),
  File "/usr/local/lib/python3.7/site-packages/requests/models.py", line 318, in prepare
    self.prepare_url(url, params)
  File "/usr/local/lib/python3.7/site-packages/requests/models.py", line 395, in prepare_url
    raise InvalidURL("Invalid URL %r: No host supplied" % url)
requests.exceptions.InvalidURL: Invalid URL 'http://:8000/line/952448': No host supplied

Exception in thread 3:
Traceback (most recent call last):
  File "/usr/local/lib/python3.7/threading.py", line 917, in _bootstrap_inner
    self.run()
  File "/usr/local/lib/python3.7/threading.py", line 865, in run
    self._target(*self._args, **self._kwargs)
  File "app.py", line 56, in _kubernetes_job
    _write_work(**kwargs)
  File "app.py", line 66, in _write_work
    gibberish_content = kwargs["gibberish_content"]
KeyError: 'gibberish_content'

