1654482742316438686;184110004
1654482742800512262;483678980
1654482743702642739;900410258
1654482746205389776;501896558
1654482746825841126;408967989
1654482747105425721;278996471
1654482747403261362;296905482
1654482750013125705;406122582
1654482750110102073;89466046
1654482756304209598;288879317
1654482757329122753;614796986
1654482760315894619;1023075100
1654482760516300669;199602827
1654482762619776409;727104945
1654482765698333663;665354782
1654482766430965968;731687909
1654482769822347981;719979898
1654482772043916271;323709728
1654482774625120284;415688273
1654482775001663084;307507024
1654482775193525984;190889201
1654482778018214223;223871283
1654482778515198354;495972317
1654482781816279991;592016538
1654482785535688966;242788956
1654482791729222698;430784734
1654482794818604458;193450016
1654482797818078838;585286583
1654482798316860548;496282440
1654482802229982673;385727062
1654482805438883409;912855643
1654482808293458129;962962418
1654482811331364762;310414593
1654482814903429798;683885624
1654482818101210326;487313149
1654482821603567855;888229020
1654482822242462513;616579097
1654482822836104491;506721050
1654482827002599337;507911486
1654482827398553911;388075959
Exception;in;thread;3:
Traceback;(most;recent;call;last):
;;File;"/usr/local/lib/python3.7/site-packages/urllib3/connectionpool.py",;line;710,;in;urlopen
;;;;chunked=chunked,
;;File;"/usr/local/lib/python3.7/site-packages/urllib3/connectionpool.py",;line;398,;in;_make_request
;;;;conn.request(method,;url,;**httplib_request_kw)
;;File;"/usr/local/lib/python3.7/site-packages/urllib3/connection.py",;line;239,;in;request
;;;;super(HTTPConnection,;self).request(method,;url,;body=body,;headers=headers)
;;File;"/usr/local/lib/python3.7/http/client.py",;line;1229,;in;request
;;;;self._send_request(method,;url,;body,;headers,;encode_chunked)
;;File;"/usr/local/lib/python3.7/http/client.py",;line;1275,;in;_send_request
;;;;self.endheaders(body,;encode_chunked=encode_chunked)
;;File;"/usr/local/lib/python3.7/http/client.py",;line;1224,;in;endheaders
;;;;self._send_output(message_body,;encode_chunked=encode_chunked)
;;File;"/usr/local/lib/python3.7/http/client.py",;line;1055,;in;_send_output
;;;;self.send(chunk)
;;File;"/usr/local/lib/python3.7/http/client.py",;line;977,;in;send
;;;;self.sock.sendall(data)
ConnectionResetError:;[Errno;104];Connection;reset;by;peer

During;handling;of;the;above;exception,;another;exception;occurred:

Traceback;(most;recent;call;last):
;;File;"/usr/local/lib/python3.7/site-packages/requests/adapters.py",;line;450,;in;send
;;;;timeout=timeout
;;File;"/usr/local/lib/python3.7/site-packages/urllib3/connectionpool.py",;line;786,;in;urlopen
;;;;method,;url,;error=e,;_pool=self,;_stacktrace=sys.exc_info()[2]
;;File;"/usr/local/lib/python3.7/site-packages/urllib3/util/retry.py",;line;550,;in;increment
;;;;raise;six.reraise(type(error),;error,;_stacktrace)
;;File;"/usr/local/lib/python3.7/site-packages/urllib3/packages/six.py",;line;769,;in;reraise
;;;;raise;value.with_traceback(tb)
;;File;"/usr/local/lib/python3.7/site-packages/urllib3/connectionpool.py",;line;710,;in;urlopen
;;;;chunked=chunked,
;;File;"/usr/local/lib/python3.7/site-packages/urllib3/connectionpool.py",;line;398,;in;_make_request
;;;;conn.request(method,;url,;**httplib_request_kw)
;;File;"/usr/local/lib/python3.7/site-packages/urllib3/connection.py",;line;239,;in;request
;;;;super(HTTPConnection,;self).request(method,;url,;body=body,;headers=headers)
;;File;"/usr/local/lib/python3.7/http/client.py",;line;1229,;in;request
;;;;self._send_request(method,;url,;body,;headers,;encode_chunked)
;;File;"/usr/local/lib/python3.7/http/client.py",;line;1275,;in;_send_request
;;;;self.endheaders(body,;encode_chunked=encode_chunked)
;;File;"/usr/local/lib/python3.7/http/client.py",;line;1224,;in;endheaders
;;;;self._send_output(message_body,;encode_chunked=encode_chunked)
;;File;"/usr/local/lib/python3.7/http/client.py",;line;1055,;in;_send_output
;;;;self.send(chunk)
;;File;"/usr/local/lib/python3.7/http/client.py",;line;977,;in;send
;;;;self.sock.sendall(data)
urllib3.exceptions.ProtocolError:;('Connection;aborted.',;ConnectionResetError(104,;'Connection;reset;by;peer'))

During;handling;of;the;above;exception,;another;exception;occurred:

Traceback;(most;recent;call;last):
;;File;"/usr/local/lib/python3.7/threading.py",;line;917,;in;_bootstrap_inner
;;;;self.run()
;;File;"/usr/local/lib/python3.7/threading.py",;line;865,;in;run
;;;;self._target(*self._args,;**self._kwargs)
;;File;"app.py",;line;48,;in;_kubernetes_job
;;;;_write_work(**kwargs)
;;File;"app.py",;line;67,;in;_write_work
;;;;simple_http_client_post.perform(gibberish_content)
;;File;"/app/models/simple_http_log_client.py",;line;12,;in;perform
;;;;return;self._simple_requests_scenario(body_json_content)
;;File;"/app/models/simple_http_log_client.py",;line;17,;in;_simple_requests_scenario
;;;;return;self.session.post(f"{self.api_url}/db",;json=body_json_content)
;;File;"/usr/local/lib/python3.7/site-packages/requests/sessions.py",;line;577,;in;post
;;;;return;self.request('POST',;url,;data=data,;json=json,;**kwargs)
;;File;"/usr/local/lib/python3.7/site-packages/requests/sessions.py",;line;529,;in;request
;;;;resp;=;self.send(prep,;**send_kwargs)
;;File;"/usr/local/lib/python3.7/site-packages/requests/sessions.py",;line;645,;in;send
;;;;r;=;adapter.send(request,;**kwargs)
;;File;"/usr/local/lib/python3.7/site-packages/requests/adapters.py",;line;501,;in;send
;;;;raise;ConnectionError(err,;request=request)
requests.exceptions.ConnectionError:;('Connection;aborted.',;ConnectionResetError(104,;'Connection;reset;by;peer'))
Exception;in;thread;11:
Traceback;(most;recent;call;last):
;;File;"/usr/local/lib/python3.7/site-packages/urllib3/connectionpool.py",;line;710,;in;urlopen
;;;;chunked=chunked,
;;File;"/usr/local/lib/python3.7/site-packages/urllib3/connectionpool.py",;line;449,;in;_make_request
;;;;six.raise_from(e,;None)
;;File;"<string>",;line;3,;in;raise_from
;;File;"/usr/local/lib/python3.7/site-packages/urllib3/connectionpool.py",;line;444,;in;_make_request
;;;;httplib_response;=;conn.getresponse()
;;File;"/usr/local/lib/python3.7/http/client.py",;line;1321,;in;getresponse
;;;;response.begin()
;;File;"/usr/local/lib/python3.7/http/client.py",;line;296,;in;begin
;;;;version,;status,;reason;=;self._read_status()
;;File;"/usr/local/lib/python3.7/http/client.py",;line;257,;in;_read_status
;;;;line;=;str(self.fp.readline(_MAXLINE;+;1),;"iso-8859-1")
;;File;"/usr/local/lib/python3.7/socket.py",;line;589,;in;readinto
;;;;return;self._sock.recv_into(b)
ConnectionResetError:;[Errno;104];Connection;reset;by;peer

During;handling;of;the;above;exception,;another;exception;occurred:

Traceback;(most;recent;call;last):
;;File;"/usr/local/lib/python3.7/site-packages/requests/adapters.py",;line;450,;in;send
;;;;timeout=timeout
;;File;"/usr/local/lib/python3.7/site-packages/urllib3/connectionpool.py",;line;786,;in;urlopen
;;;;method,;url,;error=e,;_pool=self,;_stacktrace=sys.exc_info()[2]
;;File;"/usr/local/lib/python3.7/site-packages/urllib3/util/retry.py",;line;550,;in;increment
;;;;raise;six.reraise(type(error),;error,;_stacktrace)
;;File;"/usr/local/lib/python3.7/site-packages/urllib3/packages/six.py",;line;769,;in;reraise
;;;;raise;value.with_traceback(tb)
;;File;"/usr/local/lib/python3.7/site-packages/urllib3/connectionpool.py",;line;710,;in;urlopen
;;;;chunked=chunked,
;;File;"/usr/local/lib/python3.7/site-packages/urllib3/connectionpool.py",;line;449,;in;_make_request
;;;;six.raise_from(e,;None)
;;File;"<string>",;line;3,;in;raise_from
;;File;"/usr/local/lib/python3.7/site-packages/urllib3/connectionpool.py",;line;444,;in;_make_request
;;;;httplib_response;=;conn.getresponse()
;;File;"/usr/local/lib/python3.7/http/client.py",;line;1321,;in;getresponse
;;;;response.begin()
;;File;"/usr/local/lib/python3.7/http/client.py",;line;296,;in;begin
;;;;version,;status,;reason;=;self._read_status()
;;File;"/usr/local/lib/python3.7/http/client.py",;line;257,;in;_read_status
;;;;line;=;str(self.fp.readline(_MAXLINE;+;1),;"iso-8859-1")
;;File;"/usr/local/lib/python3.7/socket.py",;line;589,;in;readinto
;;;;return;self._sock.recv_into(b)
urllib3.exceptions.ProtocolError:;('Connection;aborted.',;ConnectionResetError(104,;'Connection;reset;by;peer'))

During;handling;of;the;above;exception,;another;exception;occurred:

Traceback;(most;recent;call;last):
;;File;"/usr/local/lib/python3.7/threading.py",;line;917,;in;_bootstrap_inner
;;;;self.run()
;;File;"/usr/local/lib/python3.7/threading.py",;line;865,;in;run
;;;;self._target(*self._args,;**self._kwargs)
;;File;"app.py",;line;50,;in;_kubernetes_job
;;;;_read_work(**kwargs)
;;File;"app.py",;line;91,;in;_read_work
;;;;simple_http_client_get.perform(line_number=line_number)
;;File;"/app/models/simple_http_log_client.py",;line;26,;in;perform
;;;;return;self._simple_requests_scenario(line_number)
;;File;"/app/models/simple_http_log_client.py",;line;31,;in;_simple_requests_scenario
;;;;return;self.session.get(f"{self.api_url}/line/{line_number}")
;;File;"/usr/local/lib/python3.7/site-packages/requests/sessions.py",;line;542,;in;get
;;;;return;self.request('GET',;url,;**kwargs)
;;File;"/usr/local/lib/python3.7/site-packages/requests/sessions.py",;line;529,;in;request
;;;;resp;=;self.send(prep,;**send_kwargs)
;;File;"/usr/local/lib/python3.7/site-packages/requests/sessions.py",;line;645,;in;send
;;;;r;=;adapter.send(request,;**kwargs)
;;File;"/usr/local/lib/python3.7/site-packages/requests/adapters.py",;line;501,;in;send
;;;;raise;ConnectionError(err,;request=request)
requests.exceptions.ConnectionError:;('Connection;aborted.',;ConnectionResetError(104,;'Connection;reset;by;peer'))


Exception;in;thread;6:
Traceback;(most;recent;call;last):
;;File;"/usr/local/lib/python3.7/site-packages/urllib3/connectionpool.py",;line;710,;in;urlopen
;;;;chunked=chunked,
;;File;"/usr/local/lib/python3.7/site-packages/urllib3/connectionpool.py",;line;449,;in;_make_request
;;;;six.raise_from(e,;None)
;;File;"<string>",;line;3,;in;raise_from
;;File;"/usr/local/lib/python3.7/site-packages/urllib3/connectionpool.py",;line;444,;in;_make_request
;;;;httplib_response;=;conn.getresponse()
;;File;"/usr/local/lib/python3.7/http/client.py",;line;1321,;in;getresponse
;;;;response.begin()
;;File;"/usr/local/lib/python3.7/http/client.py",;line;296,;in;begin
;;;;version,;status,;reason;=;self._read_status()
;;File;"/usr/local/lib/python3.7/http/client.py",;line;257,;in;_read_status
;;;;line;=;str(self.fp.readline(_MAXLINE;+;1),;"iso-8859-1")
;;File;"/usr/local/lib/python3.7/socket.py",;line;589,;in;readinto
;;;;return;self._sock.recv_into(b)
ConnectionResetError:;[Errno;104];Connection;reset;by;peer

During;handling;of;the;above;exception,;another;exception;occurred:

Traceback;(most;recent;call;last):
;;File;"/usr/local/lib/python3.7/site-packages/requests/adapters.py",;line;450,;in;send
;;;;timeout=timeout
;;File;"/usr/local/lib/python3.7/site-packages/urllib3/connectionpool.py",;line;786,;in;urlopen
;;;;method,;url,;error=e,;_pool=self,;_stacktrace=sys.exc_info()[2]
;;File;"/usr/local/lib/python3.7/site-packages/urllib3/util/retry.py",;line;550,;in;increment
;;;;raise;six.reraise(type(error),;error,;_stacktrace)
;;File;"/usr/local/lib/python3.7/site-packages/urllib3/packages/six.py",;line;769,;in;reraise
;;;;raise;value.with_traceback(tb)
;;File;"/usr/local/lib/python3.7/site-packages/urllib3/connectionpool.py",;line;710,;in;urlopen
;;;;chunked=chunked,
;;File;"/usr/local/lib/python3.7/site-packages/urllib3/connectionpool.py",;line;449,;in;_make_request
;;;;six.raise_from(e,;None)
;;File;"<string>",;line;3,;in;raise_from
;;File;"/usr/local/lib/python3.7/site-packages/urllib3/connectionpool.py",;line;444,;in;_make_request
;;;;httplib_response;=;conn.getresponse()
;;File;"/usr/local/lib/python3.7/http/client.py",;line;1321,;in;getresponse
;;;;response.begin()
;;File;"/usr/local/lib/python3.7/http/client.py",;line;296,;in;begin
;;;;version,;status,;reason;=;self._read_status()
;;File;"/usr/local/lib/python3.7/http/client.py",;line;257,;in;_read_status
;;;;line;=;str(self.fp.readline(_MAXLINE;+;1),;"iso-8859-1")
;;File;"/usr/local/lib/python3.7/socket.py",;line;589,;in;readinto
;;;;return;self._sock.recv_into(b)
urllib3.exceptions.ProtocolError:;('Connection;aborted.',;ConnectionResetError(104,;'Connection;reset;by;peer'))

During;handling;of;the;above;exception,;another;exception;occurred:

Traceback;(most;recent;call;last):
;;File;"/usr/local/lib/python3.7/threading.py",;line;917,;in;_bootstrap_inner
;;;;self.run()
;;File;"/usr/local/lib/python3.7/threading.py",;line;865,;in;run
;;;;self._target(*self._args,;**self._kwargs)
;;File;"app.py",;line;48,;in;_kubernetes_job
;;;;_write_work(**kwargs)
;;File;"app.py",;line;67,;in;_write_work
;;;;simple_http_client_post.perform(gibberish_content)
;;File;"/app/models/simple_http_log_client.py",;line;12,;in;perform
;;;;return;self._simple_requests_scenario(body_json_content)
;;File;"/app/models/simple_http_log_client.py",;line;17,;in;_simple_requests_scenario
;;;;return;self.session.post(f"{self.api_url}/db",;json=body_json_content)
;;File;"/usr/local/lib/python3.7/site-packages/requests/sessions.py",;line;577,;in;post
;;;;return;self.request('POST',;url,;data=data,;json=json,;**kwargs)
;;File;"/usr/local/lib/python3.7/site-packages/requests/sessions.py",;line;529,;in;request
;;;;resp;=;self.send(prep,;**send_kwargs)
;;File;"/usr/local/lib/python3.7/site-packages/requests/sessions.py",;line;645,;in;send
;;;;r;=;adapter.send(request,;**kwargs)
;;File;"/usr/local/lib/python3.7/site-packages/requests/adapters.py",;line;501,;in;send
;;;;raise;ConnectionError(err,;request=request)
requests.exceptions.ConnectionError:;('Connection;aborted.',;ConnectionResetError(104,;'Connection;reset;by;peer'))

Exception;in;thread;9:
Traceback;(most;recent;call;last):
;;File;"/usr/local/lib/python3.7/site-packages/urllib3/connectionpool.py",;line;710,;in;urlopen
;;;;chunked=chunked,
;;File;"/usr/local/lib/python3.7/site-packages/urllib3/connectionpool.py",;line;449,;in;_make_request
;;;;six.raise_from(e,;None)
;;File;"<string>",;line;3,;in;raise_from
;;File;"/usr/local/lib/python3.7/site-packages/urllib3/connectionpool.py",;line;444,;in;_make_request
;;;;httplib_response;=;conn.getresponse()
;;File;"/usr/local/lib/python3.7/http/client.py",;line;1321,;in;getresponse
;;;;response.begin()
;;File;"/usr/local/lib/python3.7/http/client.py",;line;296,;in;begin
;;;;version,;status,;reason;=;self._read_status()
;;File;"/usr/local/lib/python3.7/http/client.py",;line;257,;in;_read_status
;;;;line;=;str(self.fp.readline(_MAXLINE;+;1),;"iso-8859-1")
;;File;"/usr/local/lib/python3.7/socket.py",;line;589,;in;readinto
;;;;return;self._sock.recv_into(b)
ConnectionResetError:;[Errno;104];Connection;reset;by;peer

During;handling;of;the;above;exception,;another;exception;occurred:

Traceback;(most;recent;call;last):
;;File;"/usr/local/lib/python3.7/site-packages/requests/adapters.py",;line;450,;in;send
;;;;timeout=timeout
;;File;"/usr/local/lib/python3.7/site-packages/urllib3/connectionpool.py",;line;786,;in;urlopen
;;;;method,;url,;error=e,;_pool=self,;_stacktrace=sys.exc_info()[2]
;;File;"/usr/local/lib/python3.7/site-packages/urllib3/util/retry.py",;line;550,;in;increment
;;;;raise;six.reraise(type(error),;error,;_stacktrace)
;;File;"/usr/local/lib/python3.7/site-packages/urllib3/packages/six.py",;line;769,;in;reraise
;;;;raise;value.with_traceback(tb)
;;File;"/usr/local/lib/python3.7/site-packages/urllib3/connectionpool.py",;line;710,;in;urlopen
;;;;chunked=chunked,
;;File;"/usr/local/lib/python3.7/site-packages/urllib3/connectionpool.py",;line;449,;in;_make_request
;;;;six.raise_from(e,;None)
;;File;"<string>",;line;3,;in;raise_from
;;File;"/usr/local/lib/python3.7/site-packages/urllib3/connectionpool.py",;line;444,;in;_make_request
;;;;httplib_response;=;conn.getresponse()
;;File;"/usr/local/lib/python3.7/http/client.py",;line;1321,;in;getresponse
;;;;response.begin()
;;File;"/usr/local/lib/python3.7/http/client.py",;line;296,;in;begin
;;;;version,;status,;reason;=;self._read_status()
;;File;"/usr/local/lib/python3.7/http/client.py",;line;257,;in;_read_status
;;;;line;=;str(self.fp.readline(_MAXLINE;+;1),;"iso-8859-1")
;;File;"/usr/local/lib/python3.7/socket.py",;line;589,;in;readinto
;;;;return;self._sock.recv_into(b)
urllib3.exceptions.ProtocolError:;('Connection;aborted.',;ConnectionResetError(104,;'Connection;reset;by;peer'))

During;handling;of;the;above;exception,;another;exception;occurred:

Traceback;(most;recent;call;last):
;;File;"/usr/local/lib/python3.7/threading.py",;line;917,;in;_bootstrap_inner
;;;;self.run()
;;File;"/usr/local/lib/python3.7/threading.py",;line;865,;in;run
;;;;self._target(*self._args,;**self._kwargs)
;;File;"app.py",;line;48,;in;_kubernetes_job
;;;;_write_work(**kwargs)
;;File;"app.py",;line;67,;in;_write_work
;;;;simple_http_client_post.perform(gibberish_content)
;;File;"/app/models/simple_http_log_client.py",;line;12,;in;perform
;;;;return;self._simple_requests_scenario(body_json_content)
;;File;"/app/models/simple_http_log_client.py",;line;17,;in;_simple_requests_scenario
;;;;return;self.session.post(f"{self.api_url}/db",;json=body_json_content)
;;File;"/usr/local/lib/python3.7/site-packages/requests/sessions.py",;line;577,;in;post
;;;;return;self.request('POST',;url,;data=data,;json=json,;**kwargs)
;;File;"/usr/local/lib/python3.7/site-packages/requests/sessions.py",;line;529,;in;request
;;;;resp;=;self.send(prep,;**send_kwargs)
;;File;"/usr/local/lib/python3.7/site-packages/requests/sessions.py",;line;645,;in;send
;;;;r;=;adapter.send(request,;**kwargs)
;;File;"/usr/local/lib/python3.7/site-packages/requests/adapters.py",;line;501,;in;send
;;;;raise;ConnectionError(err,;request=request)
requests.exceptions.ConnectionError:;('Connection;aborted.',;ConnectionResetError(104,;'Connection;reset;by;peer'))

Exception;in;thread;1:
Traceback;(most;recent;call;last):
;;File;"/usr/local/lib/python3.7/site-packages/urllib3/connectionpool.py",;line;710,;in;urlopen
;;;;chunked=chunked,
;;File;"/usr/local/lib/python3.7/site-packages/urllib3/connectionpool.py",;line;398,;in;_make_request
;;;;conn.request(method,;url,;**httplib_request_kw)
;;File;"/usr/local/lib/python3.7/site-packages/urllib3/connection.py",;line;239,;in;request
;;;;super(HTTPConnection,;self).request(method,;url,;body=body,;headers=headers)
;;File;"/usr/local/lib/python3.7/http/client.py",;line;1229,;in;request
;;;;self._send_request(method,;url,;body,;headers,;encode_chunked)
;;File;"/usr/local/lib/python3.7/http/client.py",;line;1275,;in;_send_request
;;;;self.endheaders(body,;encode_chunked=encode_chunked)
;;File;"/usr/local/lib/python3.7/http/client.py",;line;1224,;in;endheaders
;;;;self._send_output(message_body,;encode_chunked=encode_chunked)
;;File;"/usr/local/lib/python3.7/http/client.py",;line;1055,;in;_send_output
;;;;self.send(chunk)
;;File;"/usr/local/lib/python3.7/http/client.py",;line;977,;in;send
;;;;self.sock.sendall(data)
ConnectionResetError:;[Errno;104];Connection;reset;by;peer

During;handling;of;the;above;exception,;another;exception;occurred:

Traceback;(most;recent;call;last):
;;File;"/usr/local/lib/python3.7/site-packages/requests/adapters.py",;line;450,;in;send
;;;;timeout=timeout
;;File;"/usr/local/lib/python3.7/site-packages/urllib3/connectionpool.py",;line;786,;in;urlopen
;;;;method,;url,;error=e,;_pool=self,;_stacktrace=sys.exc_info()[2]
;;File;"/usr/local/lib/python3.7/site-packages/urllib3/util/retry.py",;line;550,;in;increment
;;;;raise;six.reraise(type(error),;error,;_stacktrace)
;;File;"/usr/local/lib/python3.7/site-packages/urllib3/packages/six.py",;line;769,;in;reraise
;;;;raise;value.with_traceback(tb)
;;File;"/usr/local/lib/python3.7/site-packages/urllib3/connectionpool.py",;line;710,;in;urlopen
;;;;chunked=chunked,
;;File;"/usr/local/lib/python3.7/site-packages/urllib3/connectionpool.py",;line;398,;in;_make_request
;;;;conn.request(method,;url,;**httplib_request_kw)
;;File;"/usr/local/lib/python3.7/site-packages/urllib3/connection.py",;line;239,;in;request
;;;;super(HTTPConnection,;self).request(method,;url,;body=body,;headers=headers)
;;File;"/usr/local/lib/python3.7/http/client.py",;line;1229,;in;request
;;;;self._send_request(method,;url,;body,;headers,;encode_chunked)
;;File;"/usr/local/lib/python3.7/http/client.py",;line;1275,;in;_send_request
;;;;self.endheaders(body,;encode_chunked=encode_chunked)
;;File;"/usr/local/lib/python3.7/http/client.py",;line;1224,;in;endheaders
;;;;self._send_output(message_body,;encode_chunked=encode_chunked)
;;File;"/usr/local/lib/python3.7/http/client.py",;line;1055,;in;_send_output
;;;;self.send(chunk)
;;File;"/usr/local/lib/python3.7/http/client.py",;line;977,;in;send
;;;;self.sock.sendall(data)
urllib3.exceptions.ProtocolError:;('Connection;aborted.',;ConnectionResetError(104,;'Connection;reset;by;peer'))

During;handling;of;the;above;exception,;another;exception;occurred:

Traceback;(most;recent;call;last):
;;File;"/usr/local/lib/python3.7/threading.py",;line;917,;in;_bootstrap_inner
;;;;self.run()
;;File;"/usr/local/lib/python3.7/threading.py",;line;865,;in;run
;;;;self._target(*self._args,;**self._kwargs)
;;File;"app.py",;line;48,;in;_kubernetes_job
;;;;_write_work(**kwargs)
;;File;"app.py",;line;64,;in;_write_work
;;;;calculate_latency_time_between_post_request(simple_http_client_post,;gibberish_content)
;;File;"app.py",;line;72,;in;calculate_latency_time_between_post_request
;;;;simple_http_client_post.perform(gibberish_content)
;;File;"/app/models/simple_http_log_client.py",;line;12,;in;perform
;;;;return;self._simple_requests_scenario(body_json_content)
;;File;"/app/models/simple_http_log_client.py",;line;17,;in;_simple_requests_scenario
;;;;return;self.session.post(f"{self.api_url}/db",;json=body_json_content)
;;File;"/usr/local/lib/python3.7/site-packages/requests/sessions.py",;line;577,;in;post
;;;;return;self.request('POST',;url,;data=data,;json=json,;**kwargs)
;;File;"/usr/local/lib/python3.7/site-packages/requests/sessions.py",;line;529,;in;request
;;;;resp;=;self.send(prep,;**send_kwargs)
;;File;"/usr/local/lib/python3.7/site-packages/requests/sessions.py",;line;645,;in;send
;;;;r;=;adapter.send(request,;**kwargs)
;;File;"/usr/local/lib/python3.7/site-packages/requests/adapters.py",;line;501,;in;send
;;;;raise;ConnectionError(err,;request=request)
requests.exceptions.ConnectionError:;('Connection;aborted.',;ConnectionResetError(104,;'Connection;reset;by;peer'))

Exception;in;thread;7:
Traceback;(most;recent;call;last):
;;File;"/usr/local/lib/python3.7/site-packages/urllib3/connection.py",;line;175,;in;_new_conn
;;;;(self._dns_host,;self.port),;self.timeout,;**extra_kw
;;File;"/usr/local/lib/python3.7/site-packages/urllib3/util/connection.py",;line;95,;in;create_connection
;;;;raise;err
;;File;"/usr/local/lib/python3.7/site-packages/urllib3/util/connection.py",;line;85,;in;create_connection
;;;;sock.connect(sa)
ConnectionRefusedError:;[Errno;111];Connection;refused

During;handling;of;the;above;exception,;another;exception;occurred:

Traceback;(most;recent;call;last):
;;File;"/usr/local/lib/python3.7/site-packages/urllib3/connectionpool.py",;line;710,;in;urlopen
;;;;chunked=chunked,
;;File;"/usr/local/lib/python3.7/site-packages/urllib3/connectionpool.py",;line;398,;in;_make_request
;;;;conn.request(method,;url,;**httplib_request_kw)
;;File;"/usr/local/lib/python3.7/site-packages/urllib3/connection.py",;line;239,;in;request
;;;;super(HTTPConnection,;self).request(method,;url,;body=body,;headers=headers)
;;File;"/usr/local/lib/python3.7/http/client.py",;line;1229,;in;request
;;;;self._send_request(method,;url,;body,;headers,;encode_chunked)
;;File;"/usr/local/lib/python3.7/http/client.py",;line;1275,;in;_send_request
;;;;self.endheaders(body,;encode_chunked=encode_chunked)
;;File;"/usr/local/lib/python3.7/http/client.py",;line;1224,;in;endheaders
;;;;self._send_output(message_body,;encode_chunked=encode_chunked)
;;File;"/usr/local/lib/python3.7/http/client.py",;line;1016,;in;_send_output
;;;;self.send(msg)
;;File;"/usr/local/lib/python3.7/http/client.py",;line;956,;in;send
;;;;self.connect()
;;File;"/usr/local/lib/python3.7/site-packages/urllib3/connection.py",;line;205,;in;connect
;;;;conn;=;self._new_conn()
;;File;"/usr/local/lib/python3.7/site-packages/urllib3/connection.py",;line;187,;in;_new_conn
;;;;self,;"Failed;to;establish;a;new;connection:;%s";%;e
urllib3.exceptions.NewConnectionError:;<urllib3.connection.HTTPConnection;object;at;0x7fe8b5b8f3c8>:;Failed;to;establish;a;new;connection:;[Errno;111];Connection;refused

During;handling;of;the;above;exception,;another;exception;occurred:

Traceback;(most;recent;call;last):
;;File;"/usr/local/lib/python3.7/site-packages/requests/adapters.py",;line;450,;in;send
;;;;timeout=timeout
;;File;"/usr/local/lib/python3.7/site-packages/urllib3/connectionpool.py",;line;786,;in;urlopen
;;;;method,;url,;error=e,;_pool=self,;_stacktrace=sys.exc_info()[2]
;;File;"/usr/local/lib/python3.7/site-packages/urllib3/util/retry.py",;line;592,;in;increment
;;;;raise;MaxRetryError(_pool,;url,;error;or;ResponseError(cause))
urllib3.exceptions.MaxRetryError:;HTTPConnectionPool(host='hermes-leader',;port=8000):;Max;retries;exceeded;with;url:;/db;(Caused;by;NewConnectionError('<urllib3.connection.HTTPConnection;object;at;0x7fe8b5b8f3c8>:;Failed;to;establish;a;new;connection:;[Errno;111];Connection;refused'))

During;handling;of;the;above;exception,;another;exception;occurred:

Traceback;(most;recent;call;last):
;;File;"/usr/local/lib/python3.7/threading.py",;line;917,;in;_bootstrap_inner
;;;;self.run()
;;File;"/usr/local/lib/python3.7/threading.py",;line;865,;in;run
;;;;self._target(*self._args,;**self._kwargs)
;;File;"app.py",;line;48,;in;_kubernetes_job
;;;;_write_work(**kwargs)
;;File;"app.py",;line;67,;in;_write_work
;;;;simple_http_client_post.perform(gibberish_content)
;;File;"/app/models/simple_http_log_client.py",;line;12,;in;perform
;;;;return;self._simple_requests_scenario(body_json_content)
;;File;"/app/models/simple_http_log_client.py",;line;17,;in;_simple_requests_scenario
;;;;return;self.session.post(f"{self.api_url}/db",;json=body_json_content)
;;File;"/usr/local/lib/python3.7/site-packages/requests/sessions.py",;line;577,;in;post
;;;;return;self.request('POST',;url,;data=data,;json=json,;**kwargs)
;;File;"/usr/local/lib/python3.7/site-packages/requests/sessions.py",;line;529,;in;request
;;;;resp;=;self.send(prep,;**send_kwargs)
;;File;"/usr/local/lib/python3.7/site-packages/requests/sessions.py",;line;645,;in;send
;;;;r;=;adapter.send(request,;**kwargs)
;;File;"/usr/local/lib/python3.7/site-packages/requests/adapters.py",;line;519,;in;send
;;;;raise;ConnectionError(e,;request=request)
requests.exceptions.ConnectionError:;HTTPConnectionPool(host='hermes-leader',;port=8000):;Max;retries;exceeded;with;url:;/db;(Caused;by;NewConnectionError('<urllib3.connection.HTTPConnection;object;at;0x7fe8b5b8f3c8>:;Failed;to;establish;a;new;connection:;[Errno;111];Connection;refused'))

Exception;in;thread;Thread-1:
Traceback;(most;recent;call;last):
;;File;"/usr/local/lib/python3.7/site-packages/urllib3/connection.py",;line;175,;in;_new_conn
;;;;(self._dns_host,;self.port),;self.timeout,;**extra_kw
;;File;"/usr/local/lib/python3.7/site-packages/urllib3/util/connection.py",;line;95,;in;create_connection
;;;;raise;err
;;File;"/usr/local/lib/python3.7/site-packages/urllib3/util/connection.py",;line;85,;in;create_connection
;;;;sock.connect(sa)
ConnectionRefusedError:;[Errno;111];Connection;refused

During;handling;of;the;above;exception,;another;exception;occurred:

Traceback;(most;recent;call;last):
;;File;"/usr/local/lib/python3.7/site-packages/urllib3/connectionpool.py",;line;710,;in;urlopen
;;;;chunked=chunked,
;;File;"/usr/local/lib/python3.7/site-packages/urllib3/connectionpool.py",;line;398,;in;_make_request
;;;;conn.request(method,;url,;**httplib_request_kw)
;;File;"/usr/local/lib/python3.7/site-packages/urllib3/connection.py",;line;239,;in;request
;;;;super(HTTPConnection,;self).request(method,;url,;body=body,;headers=headers)
;;File;"/usr/local/lib/python3.7/http/client.py",;line;1229,;in;request
;;;;self._send_request(method,;url,;body,;headers,;encode_chunked)
;;File;"/usr/local/lib/python3.7/http/client.py",;line;1275,;in;_send_request
;;;;self.endheaders(body,;encode_chunked=encode_chunked)
;;File;"/usr/local/lib/python3.7/http/client.py",;line;1224,;in;endheaders
;;;;self._send_output(message_body,;encode_chunked=encode_chunked)
;;File;"/usr/local/lib/python3.7/http/client.py",;line;1016,;in;_send_output
;;;;self.send(msg)
;;File;"/usr/local/lib/python3.7/http/client.py",;line;956,;in;send
;;;;self.connect()
;;File;"/usr/local/lib/python3.7/site-packages/urllib3/connection.py",;line;205,;in;connect
;;;;conn;=;self._new_conn()
;;File;"/usr/local/lib/python3.7/site-packages/urllib3/connection.py",;line;187,;in;_new_conn
;;;;self,;"Failed;to;establish;a;new;connection:;%s";%;e
urllib3.exceptions.NewConnectionError:;<urllib3.connection.HTTPConnection;object;at;0x7fe8a43236d8>:;Failed;to;establish;a;new;connection:;[Errno;111];Connection;refused

During;handling;of;the;above;exception,;another;exception;occurred:

Traceback;(most;recent;call;last):
;;File;"/usr/local/lib/python3.7/site-packages/requests/adapters.py",;line;450,;in;send
;;;;timeout=timeout
;;File;"/usr/local/lib/python3.7/site-packages/urllib3/connectionpool.py",;line;786,;in;urlopen
;;;;method,;url,;error=e,;_pool=self,;_stacktrace=sys.exc_info()[2]
;;File;"/usr/local/lib/python3.7/site-packages/urllib3/util/retry.py",;line;592,;in;increment
;;;;raise;MaxRetryError(_pool,;url,;error;or;ResponseError(cause))
urllib3.exceptions.MaxRetryError:;HTTPConnectionPool(host='hermes-leader',;port=8000):;Max;retries;exceeded;with;url:;/db;(Caused;by;NewConnectionError('<urllib3.connection.HTTPConnection;object;at;0x7fe8a43236d8>:;Failed;to;establish;a;new;connection:;[Errno;111];Connection;refused'))

During;handling;of;the;above;exception,;another;exception;occurred:

Traceback;(most;recent;call;last):
;;File;"/usr/local/lib/python3.7/threading.py",;line;917,;in;_bootstrap_inner
;;;;self.run()
;;File;"/usr/local/lib/python3.7/threading.py",;line;865,;in;run
;;;;self._target(*self._args,;**self._kwargs)
;;File;"app.py",;line;48,;in;_kubernetes_job
;;;;_write_work(**kwargs)
;;File;"app.py",;line;67,;in;_write_work
;;;;simple_http_client_post.perform(gibberish_content)
;;File;"/app/models/simple_http_log_client.py",;line;12,;in;perform
;;;;return;self._simple_requests_scenario(body_json_content)
;;File;"/app/models/simple_http_log_client.py",;line;17,;in;_simple_requests_scenario
;;;;return;self.session.post(f"{self.api_url}/db",;json=body_json_content)
;;File;"/usr/local/lib/python3.7/site-packages/requests/sessions.py",;line;577,;in;post
;;;;return;self.request('POST',;url,;data=data,;json=json,;**kwargs)
;;File;"/usr/local/lib/python3.7/site-packages/requests/sessions.py",;line;529,;in;request
;;;;resp;=;self.send(prep,;**send_kwargs)
;;File;"/usr/local/lib/python3.7/site-packages/requests/sessions.py",;line;645,;in;send
;;;;r;=;adapter.send(request,;**kwargs)
;;File;"/usr/local/lib/python3.7/site-packages/requests/adapters.py",;line;519,;in;send
;;;;raise;ConnectionError(e,;request=request)
requests.exceptions.ConnectionError:;HTTPConnectionPool(host='hermes-leader',;port=8000):;Max;retries;exceeded;with;url:;/db;(Caused;by;NewConnectionError('<urllib3.connection.HTTPConnection;object;at;0x7fe8a43236d8>:;Failed;to;establish;a;new;connection:;[Errno;111];Connection;refused'))

Exception;in;thread;8:
Traceback;(most;recent;call;last):
;;File;"/usr/local/lib/python3.7/site-packages/urllib3/connection.py",;line;175,;in;_new_conn
;;;;(self._dns_host,;self.port),;self.timeout,;**extra_kw
;;File;"/usr/local/lib/python3.7/site-packages/urllib3/util/connection.py",;line;95,;in;create_connection
;;;;raise;err
;;File;"/usr/local/lib/python3.7/site-packages/urllib3/util/connection.py",;line;85,;in;create_connection
;;;;sock.connect(sa)
ConnectionRefusedError:;[Errno;111];Connection;refused

During;handling;of;the;above;exception,;another;exception;occurred:

Traceback;(most;recent;call;last):
;;File;"/usr/local/lib/python3.7/site-packages/urllib3/connectionpool.py",;line;710,;in;urlopen
;;;;chunked=chunked,
;;File;"/usr/local/lib/python3.7/site-packages/urllib3/connectionpool.py",;line;398,;in;_make_request
;;;;conn.request(method,;url,;**httplib_request_kw)
;;File;"/usr/local/lib/python3.7/site-packages/urllib3/connection.py",;line;239,;in;request
;;;;super(HTTPConnection,;self).request(method,;url,;body=body,;headers=headers)
;;File;"/usr/local/lib/python3.7/http/client.py",;line;1229,;in;request
;;;;self._send_request(method,;url,;body,;headers,;encode_chunked)
;;File;"/usr/local/lib/python3.7/http/client.py",;line;1275,;in;_send_request
;;;;self.endheaders(body,;encode_chunked=encode_chunked)
;;File;"/usr/local/lib/python3.7/http/client.py",;line;1224,;in;endheaders
;;;;self._send_output(message_body,;encode_chunked=encode_chunked)
;;File;"/usr/local/lib/python3.7/http/client.py",;line;1016,;in;_send_output
;;;;self.send(msg)
;;File;"/usr/local/lib/python3.7/http/client.py",;line;956,;in;send
;;;;self.connect()
;;File;"/usr/local/lib/python3.7/site-packages/urllib3/connection.py",;line;205,;in;connect
;;;;conn;=;self._new_conn()
;;File;"/usr/local/lib/python3.7/site-packages/urllib3/connection.py",;line;187,;in;_new_conn
;;;;self,;"Failed;to;establish;a;new;connection:;%s";%;e
urllib3.exceptions.NewConnectionError:;<urllib3.connection.HTTPConnection;object;at;0x7fe8a42f5eb8>:;Failed;to;establish;a;new;connection:;[Errno;111];Connection;refused

During;handling;of;the;above;exception,;another;exception;occurred:

Traceback;(most;recent;call;last):
;;File;"/usr/local/lib/python3.7/site-packages/requests/adapters.py",;line;450,;in;send
;;;;timeout=timeout
;;File;"/usr/local/lib/python3.7/site-packages/urllib3/connectionpool.py",;line;786,;in;urlopen
;;;;method,;url,;error=e,;_pool=self,;_stacktrace=sys.exc_info()[2]
;;File;"/usr/local/lib/python3.7/site-packages/urllib3/util/retry.py",;line;592,;in;increment
;;;;raise;MaxRetryError(_pool,;url,;error;or;ResponseError(cause))
urllib3.exceptions.MaxRetryError:;HTTPConnectionPool(host='hermes-leader',;port=8000):;Max;retries;exceeded;with;url:;/db;(Caused;by;NewConnectionError('<urllib3.connection.HTTPConnection;object;at;0x7fe8a42f5eb8>:;Failed;to;establish;a;new;connection:;[Errno;111];Connection;refused'))

During;handling;of;the;above;exception,;another;exception;occurred:

Traceback;(most;recent;call;last):
;;File;"/usr/local/lib/python3.7/threading.py",;line;917,;in;_bootstrap_inner
;;;;self.run()
;;File;"/usr/local/lib/python3.7/threading.py",;line;865,;in;run
;;;;self._target(*self._args,;**self._kwargs)
;;File;"app.py",;line;48,;in;_kubernetes_job
;;;;_write_work(**kwargs)
;;File;"app.py",;line;67,;in;_write_work
;;;;simple_http_client_post.perform(gibberish_content)
;;File;"/app/models/simple_http_log_client.py",;line;12,;in;perform
;;;;return;self._simple_requests_scenario(body_json_content)
;;File;"/app/models/simple_http_log_client.py",;line;17,;in;_simple_requests_scenario
;;;;return;self.session.post(f"{self.api_url}/db",;json=body_json_content)
;;File;"/usr/local/lib/python3.7/site-packages/requests/sessions.py",;line;577,;in;post
;;;;return;self.request('POST',;url,;data=data,;json=json,;**kwargs)
;;File;"/usr/local/lib/python3.7/site-packages/requests/sessions.py",;line;529,;in;request
;;;;resp;=;self.send(prep,;**send_kwargs)
;;File;"/usr/local/lib/python3.7/site-packages/requests/sessions.py",;line;645,;in;send
;;;;r;=;adapter.send(request,;**kwargs)
;;File;"/usr/local/lib/python3.7/site-packages/requests/adapters.py",;line;519,;in;send
;;;;raise;ConnectionError(e,;request=request)
requests.exceptions.ConnectionError:;HTTPConnectionPool(host='hermes-leader',;port=8000):;Max;retries;exceeded;with;url:;/db;(Caused;by;NewConnectionError('<urllib3.connection.HTTPConnection;object;at;0x7fe8a42f5eb8>:;Failed;to;establish;a;new;connection:;[Errno;111];Connection;refused'))

Exception;in;thread;5:
Traceback;(most;recent;call;last):
;;File;"/usr/local/lib/python3.7/site-packages/urllib3/connection.py",;line;175,;in;_new_conn
;;;;(self._dns_host,;self.port),;self.timeout,;**extra_kw
;;File;"/usr/local/lib/python3.7/site-packages/urllib3/util/connection.py",;line;95,;in;create_connection
;;;;raise;err
;;File;"/usr/local/lib/python3.7/site-packages/urllib3/util/connection.py",;line;85,;in;create_connection
;;;;sock.connect(sa)
ConnectionRefusedError:;[Errno;111];Connection;refused

During;handling;of;the;above;exception,;another;exception;occurred:

Traceback;(most;recent;call;last):
;;File;"/usr/local/lib/python3.7/site-packages/urllib3/connectionpool.py",;line;710,;in;urlopen
;;;;chunked=chunked,
;;File;"/usr/local/lib/python3.7/site-packages/urllib3/connectionpool.py",;line;398,;in;_make_request
;;;;conn.request(method,;url,;**httplib_request_kw)
;;File;"/usr/local/lib/python3.7/site-packages/urllib3/connection.py",;line;239,;in;request
;;;;super(HTTPConnection,;self).request(method,;url,;body=body,;headers=headers)
;;File;"/usr/local/lib/python3.7/http/client.py",;line;1229,;in;request
;;;;self._send_request(method,;url,;body,;headers,;encode_chunked)
;;File;"/usr/local/lib/python3.7/http/client.py",;line;1275,;in;_send_request
;;;;self.endheaders(body,;encode_chunked=encode_chunked)
;;File;"/usr/local/lib/python3.7/http/client.py",;line;1224,;in;endheaders
;;;;self._send_output(message_body,;encode_chunked=encode_chunked)
;;File;"/usr/local/lib/python3.7/http/client.py",;line;1016,;in;_send_output
;;;;self.send(msg)
;;File;"/usr/local/lib/python3.7/http/client.py",;line;956,;in;send
;;;;self.connect()
;;File;"/usr/local/lib/python3.7/site-packages/urllib3/connection.py",;line;205,;in;connect
;;;;conn;=;self._new_conn()
;;File;"/usr/local/lib/python3.7/site-packages/urllib3/connection.py",;line;187,;in;_new_conn
;;;;self,;"Failed;to;establish;a;new;connection:;%s";%;e
urllib3.exceptions.NewConnectionError:;<urllib3.connection.HTTPConnection;object;at;0x7fe8b5b7e7f0>:;Failed;to;establish;a;new;connection:;[Errno;111];Connection;refused

During;handling;of;the;above;exception,;another;exception;occurred:

Traceback;(most;recent;call;last):
;;File;"/usr/local/lib/python3.7/site-packages/requests/adapters.py",;line;450,;in;send
;;;;timeout=timeout
;;File;"/usr/local/lib/python3.7/site-packages/urllib3/connectionpool.py",;line;786,;in;urlopen
;;;;method,;url,;error=e,;_pool=self,;_stacktrace=sys.exc_info()[2]
;;File;"/usr/local/lib/python3.7/site-packages/urllib3/util/retry.py",;line;592,;in;increment
;;;;raise;MaxRetryError(_pool,;url,;error;or;ResponseError(cause))
urllib3.exceptions.MaxRetryError:;HTTPConnectionPool(host='hermes-leader',;port=8000):;Max;retries;exceeded;with;url:;/line/774;(Caused;by;NewConnectionError('<urllib3.connection.HTTPConnection;object;at;0x7fe8b5b7e7f0>:;Failed;to;establish;a;new;connection:;[Errno;111];Connection;refused'))

During;handling;of;the;above;exception,;another;exception;occurred:

Traceback;(most;recent;call;last):
;;File;"/usr/local/lib/python3.7/threading.py",;line;917,;in;_bootstrap_inner
;;;;self.run()
;;File;"/usr/local/lib/python3.7/threading.py",;line;865,;in;run
;;;;self._target(*self._args,;**self._kwargs)
;;File;"app.py",;line;50,;in;_kubernetes_job
;;;;_read_work(**kwargs)
;;File;"app.py",;line;91,;in;_read_work
;;;;simple_http_client_get.perform(line_number=line_number)
;;File;"/app/models/simple_http_log_client.py",;line;26,;in;perform
;;;;return;self._simple_requests_scenario(line_number)
;;File;"/app/models/simple_http_log_client.py",;line;31,;in;_simple_requests_scenario
;;;;return;self.session.get(f"{self.api_url}/line/{line_number}")
;;File;"/usr/local/lib/python3.7/site-packages/requests/sessions.py",;line;542,;in;get
;;;;return;self.request('GET',;url,;**kwargs)
;;File;"/usr/local/lib/python3.7/site-packages/requests/sessions.py",;line;529,;in;request
;;;;resp;=;self.send(prep,;**send_kwargs)
;;File;"/usr/local/lib/python3.7/site-packages/requests/sessions.py",;line;645,;in;send
;;;;r;=;adapter.send(request,;**kwargs)
;;File;"/usr/local/lib/python3.7/site-packages/requests/adapters.py",;line;519,;in;send
;;;;raise;ConnectionError(e,;request=request)
requests.exceptions.ConnectionError:;HTTPConnectionPool(host='hermes-leader',;port=8000):;Max;retries;exceeded;with;url:;/line/774;(Caused;by;NewConnectionError('<urllib3.connection.HTTPConnection;object;at;0x7fe8b5b7e7f0>:;Failed;to;establish;a;new;connection:;[Errno;111];Connection;refused'))

Exception;in;thread;2:
Traceback;(most;recent;call;last):
;;File;"/usr/local/lib/python3.7/site-packages/urllib3/connection.py",;line;175,;in;_new_conn
;;;;(self._dns_host,;self.port),;self.timeout,;**extra_kw
;;File;"/usr/local/lib/python3.7/site-packages/urllib3/util/connection.py",;line;95,;in;create_connection
;;;;raise;err
;;File;"/usr/local/lib/python3.7/site-packages/urllib3/util/connection.py",;line;85,;in;create_connection
;;;;sock.connect(sa)
ConnectionRefusedError:;[Errno;111];Connection;refused

During;handling;of;the;above;exception,;another;exception;occurred:

Traceback;(most;recent;call;last):
;;File;"/usr/local/lib/python3.7/site-packages/urllib3/connectionpool.py",;line;710,;in;urlopen
;;;;chunked=chunked,
;;File;"/usr/local/lib/python3.7/site-packages/urllib3/connectionpool.py",;line;398,;in;_make_request
;;;;conn.request(method,;url,;**httplib_request_kw)
;;File;"/usr/local/lib/python3.7/site-packages/urllib3/connection.py",;line;239,;in;request
;;;;super(HTTPConnection,;self).request(method,;url,;body=body,;headers=headers)
;;File;"/usr/local/lib/python3.7/http/client.py",;line;1229,;in;request
;;;;self._send_request(method,;url,;body,;headers,;encode_chunked)
;;File;"/usr/local/lib/python3.7/http/client.py",;line;1275,;in;_send_request
;;;;self.endheaders(body,;encode_chunked=encode_chunked)
;;File;"/usr/local/lib/python3.7/http/client.py",;line;1224,;in;endheaders
;;;;self._send_output(message_body,;encode_chunked=encode_chunked)
;;File;"/usr/local/lib/python3.7/http/client.py",;line;1016,;in;_send_output
;;;;self.send(msg)
;;File;"/usr/local/lib/python3.7/http/client.py",;line;956,;in;send
;;;;self.connect()
;;File;"/usr/local/lib/python3.7/site-packages/urllib3/connection.py",;line;205,;in;connect
;;;;conn;=;self._new_conn()
;;File;"/usr/local/lib/python3.7/site-packages/urllib3/connection.py",;line;187,;in;_new_conn
;;;;self,;"Failed;to;establish;a;new;connection:;%s";%;e
urllib3.exceptions.NewConnectionError:;<urllib3.connection.HTTPConnection;object;at;0x7fe8b5b54198>:;Failed;to;establish;a;new;connection:;[Errno;111];Connection;refused

During;handling;of;the;above;exception,;another;exception;occurred:

Traceback;(most;recent;call;last):
;;File;"/usr/local/lib/python3.7/site-packages/requests/adapters.py",;line;450,;in;send
;;;;timeout=timeout
;;File;"/usr/local/lib/python3.7/site-packages/urllib3/connectionpool.py",;line;786,;in;urlopen
;;;;method,;url,;error=e,;_pool=self,;_stacktrace=sys.exc_info()[2]
;;File;"/usr/local/lib/python3.7/site-packages/urllib3/util/retry.py",;line;592,;in;increment
;;;;raise;MaxRetryError(_pool,;url,;error;or;ResponseError(cause))
urllib3.exceptions.MaxRetryError:;HTTPConnectionPool(host='hermes-leader',;port=8000):;Max;retries;exceeded;with;url:;/db;(Caused;by;NewConnectionError('<urllib3.connection.HTTPConnection;object;at;0x7fe8b5b54198>:;Failed;to;establish;a;new;connection:;[Errno;111];Connection;refused'))

During;handling;of;the;above;exception,;another;exception;occurred:

Traceback;(most;recent;call;last):
;;File;"/usr/local/lib/python3.7/threading.py",;line;917,;in;_bootstrap_inner
;;;;self.run()
;;File;"/usr/local/lib/python3.7/threading.py",;line;865,;in;run
;;;;self._target(*self._args,;**self._kwargs)
;;File;"app.py",;line;48,;in;_kubernetes_job
;;;;_write_work(**kwargs)
;;File;"app.py",;line;67,;in;_write_work
;;;;simple_http_client_post.perform(gibberish_content)
;;File;"/app/models/simple_http_log_client.py",;line;12,;in;perform
;;;;return;self._simple_requests_scenario(body_json_content)
;;File;"/app/models/simple_http_log_client.py",;line;17,;in;_simple_requests_scenario
;;;;return;self.session.post(f"{self.api_url}/db",;json=body_json_content)
;;File;"/usr/local/lib/python3.7/site-packages/requests/sessions.py",;line;577,;in;post
;;;;return;self.request('POST',;url,;data=data,;json=json,;**kwargs)
;;File;"/usr/local/lib/python3.7/site-packages/requests/sessions.py",;line;529,;in;request
;;;;resp;=;self.send(prep,;**send_kwargs)
;;File;"/usr/local/lib/python3.7/site-packages/requests/sessions.py",;line;645,;in;send
;;;;r;=;adapter.send(request,;**kwargs)
;;File;"/usr/local/lib/python3.7/site-packages/requests/adapters.py",;line;519,;in;send
;;;;raise;ConnectionError(e,;request=request)
requests.exceptions.ConnectionError:;HTTPConnectionPool(host='hermes-leader',;port=8000):;Max;retries;exceeded;with;url:;/db;(Caused;by;NewConnectionError('<urllib3.connection.HTTPConnection;object;at;0x7fe8b5b54198>:;Failed;to;establish;a;new;connection:;[Errno;111];Connection;refused'))

Exception;in;thread;12:
Traceback;(most;recent;call;last):
;;File;"/usr/local/lib/python3.7/site-packages/urllib3/connection.py",;line;175,;in;_new_conn
;;;;(self._dns_host,;self.port),;self.timeout,;**extra_kw
;;File;"/usr/local/lib/python3.7/site-packages/urllib3/util/connection.py",;line;95,;in;create_connection
;;;;raise;err
;;File;"/usr/local/lib/python3.7/site-packages/urllib3/util/connection.py",;line;85,;in;create_connection
;;;;sock.connect(sa)
ConnectionRefusedError:;[Errno;111];Connection;refused

During;handling;of;the;above;exception,;another;exception;occurred:

Traceback;(most;recent;call;last):
;;File;"/usr/local/lib/python3.7/site-packages/urllib3/connectionpool.py",;line;710,;in;urlopen
;;;;chunked=chunked,
;;File;"/usr/local/lib/python3.7/site-packages/urllib3/connectionpool.py",;line;398,;in;_make_request
;;;;conn.request(method,;url,;**httplib_request_kw)
;;File;"/usr/local/lib/python3.7/site-packages/urllib3/connection.py",;line;239,;in;request
;;;;super(HTTPConnection,;self).request(method,;url,;body=body,;headers=headers)
;;File;"/usr/local/lib/python3.7/http/client.py",;line;1229,;in;request
;;;;self._send_request(method,;url,;body,;headers,;encode_chunked)
;;File;"/usr/local/lib/python3.7/http/client.py",;line;1275,;in;_send_request
;;;;self.endheaders(body,;encode_chunked=encode_chunked)
;;File;"/usr/local/lib/python3.7/http/client.py",;line;1224,;in;endheaders
;;;;self._send_output(message_body,;encode_chunked=encode_chunked)
;;File;"/usr/local/lib/python3.7/http/client.py",;line;1016,;in;_send_output
;;;;self.send(msg)
;;File;"/usr/local/lib/python3.7/http/client.py",;line;956,;in;send
;;;;self.connect()
;;File;"/usr/local/lib/python3.7/site-packages/urllib3/connection.py",;line;205,;in;connect
;;;;conn;=;self._new_conn()
;;File;"/usr/local/lib/python3.7/site-packages/urllib3/connection.py",;line;187,;in;_new_conn
;;;;self,;"Failed;to;establish;a;new;connection:;%s";%;e
urllib3.exceptions.NewConnectionError:;<urllib3.connection.HTTPConnection;object;at;0x7fe8b5c07240>:;Failed;to;establish;a;new;connection:;[Errno;111];Connection;refused

During;handling;of;the;above;exception,;another;exception;occurred:

Traceback;(most;recent;call;last):
;;File;"/usr/local/lib/python3.7/site-packages/requests/adapters.py",;line;450,;in;send
;;;;timeout=timeout
;;File;"/usr/local/lib/python3.7/site-packages/urllib3/connectionpool.py",;line;786,;in;urlopen
;;;;method,;url,;error=e,;_pool=self,;_stacktrace=sys.exc_info()[2]
;;File;"/usr/local/lib/python3.7/site-packages/urllib3/util/retry.py",;line;592,;in;increment
;;;;raise;MaxRetryError(_pool,;url,;error;or;ResponseError(cause))
urllib3.exceptions.MaxRetryError:;HTTPConnectionPool(host='hermes-leader',;port=8000):;Max;retries;exceeded;with;url:;/db;(Caused;by;NewConnectionError('<urllib3.connection.HTTPConnection;object;at;0x7fe8b5c07240>:;Failed;to;establish;a;new;connection:;[Errno;111];Connection;refused'))

During;handling;of;the;above;exception,;another;exception;occurred:

Traceback;(most;recent;call;last):
;;File;"/usr/local/lib/python3.7/threading.py",;line;917,;in;_bootstrap_inner
;;;;self.run()
;;File;"/usr/local/lib/python3.7/threading.py",;line;865,;in;run
;;;;self._target(*self._args,;**self._kwargs)
;;File;"app.py",;line;48,;in;_kubernetes_job
;;;;_write_work(**kwargs)
;;File;"app.py",;line;67,;in;_write_work
;;;;simple_http_client_post.perform(gibberish_content)
;;File;"/app/models/simple_http_log_client.py",;line;12,;in;perform
;;;;return;self._simple_requests_scenario(body_json_content)
;;File;"/app/models/simple_http_log_client.py",;line;17,;in;_simple_requests_scenario
;;;;return;self.session.post(f"{self.api_url}/db",;json=body_json_content)
;;File;"/usr/local/lib/python3.7/site-packages/requests/sessions.py",;line;577,;in;post
;;;;return;self.request('POST',;url,;data=data,;json=json,;**kwargs)
;;File;"/usr/local/lib/python3.7/site-packages/requests/sessions.py",;line;529,;in;request
;;;;resp;=;self.send(prep,;**send_kwargs)
;;File;"/usr/local/lib/python3.7/site-packages/requests/sessions.py",;line;645,;in;send
;;;;r;=;adapter.send(request,;**kwargs)
;;File;"/usr/local/lib/python3.7/site-packages/requests/adapters.py",;line;519,;in;send
;;;;raise;ConnectionError(e,;request=request)
requests.exceptions.ConnectionError:;HTTPConnectionPool(host='hermes-leader',;port=8000):;Max;retries;exceeded;with;url:;/db;(Caused;by;NewConnectionError('<urllib3.connection.HTTPConnection;object;at;0x7fe8b5c07240>:;Failed;to;establish;a;new;connection:;[Errno;111];Connection;refused'))

Exception;in;thread;13:
Traceback;(most;recent;call;last):
;;File;"/usr/local/lib/python3.7/site-packages/urllib3/connection.py",;line;175,;in;_new_conn
;;;;(self._dns_host,;self.port),;self.timeout,;**extra_kw
;;File;"/usr/local/lib/python3.7/site-packages/urllib3/util/connection.py",;line;95,;in;create_connection
;;;;raise;err
;;File;"/usr/local/lib/python3.7/site-packages/urllib3/util/connection.py",;line;85,;in;create_connection
;;;;sock.connect(sa)
ConnectionRefusedError:;[Errno;111];Connection;refused

During;handling;of;the;above;exception,;another;exception;occurred:

Traceback;(most;recent;call;last):
;;File;"/usr/local/lib/python3.7/site-packages/urllib3/connectionpool.py",;line;710,;in;urlopen
;;;;chunked=chunked,
;;File;"/usr/local/lib/python3.7/site-packages/urllib3/connectionpool.py",;line;398,;in;_make_request
;;;;conn.request(method,;url,;**httplib_request_kw)
;;File;"/usr/local/lib/python3.7/site-packages/urllib3/connection.py",;line;239,;in;request
;;;;super(HTTPConnection,;self).request(method,;url,;body=body,;headers=headers)
;;File;"/usr/local/lib/python3.7/http/client.py",;line;1229,;in;request
;;;;self._send_request(method,;url,;body,;headers,;encode_chunked)
;;File;"/usr/local/lib/python3.7/http/client.py",;line;1275,;in;_send_request
;;;;self.endheaders(body,;encode_chunked=encode_chunked)
;;File;"/usr/local/lib/python3.7/http/client.py",;line;1224,;in;endheaders
;;;;self._send_output(message_body,;encode_chunked=encode_chunked)
;;File;"/usr/local/lib/python3.7/http/client.py",;line;1016,;in;_send_output
;;;;self.send(msg)
;;File;"/usr/local/lib/python3.7/http/client.py",;line;956,;in;send
;;;;self.connect()
;;File;"/usr/local/lib/python3.7/site-packages/urllib3/connection.py",;line;205,;in;connect
;;;;conn;=;self._new_conn()
;;File;"/usr/local/lib/python3.7/site-packages/urllib3/connection.py",;line;187,;in;_new_conn
;;;;self,;"Failed;to;establish;a;new;connection:;%s";%;e
urllib3.exceptions.NewConnectionError:;<urllib3.connection.HTTPConnection;object;at;0x7fe8b5b65940>:;Failed;to;establish;a;new;connection:;[Errno;111];Connection;refused

During;handling;of;the;above;exception,;another;exception;occurred:

Traceback;(most;recent;call;last):
;;File;"/usr/local/lib/python3.7/site-packages/requests/adapters.py",;line;450,;in;send
;;;;timeout=timeout
;;File;"/usr/local/lib/python3.7/site-packages/urllib3/connectionpool.py",;line;786,;in;urlopen
;;;;method,;url,;error=e,;_pool=self,;_stacktrace=sys.exc_info()[2]
;;File;"/usr/local/lib/python3.7/site-packages/urllib3/util/retry.py",;line;592,;in;increment
;;;;raise;MaxRetryError(_pool,;url,;error;or;ResponseError(cause))
urllib3.exceptions.MaxRetryError:;HTTPConnectionPool(host='hermes-leader',;port=8000):;Max;retries;exceeded;with;url:;/db;(Caused;by;NewConnectionError('<urllib3.connection.HTTPConnection;object;at;0x7fe8b5b65940>:;Failed;to;establish;a;new;connection:;[Errno;111];Connection;refused'))

During;handling;of;the;above;exception,;another;exception;occurred:

Traceback;(most;recent;call;last):
;;File;"/usr/local/lib/python3.7/threading.py",;line;917,;in;_bootstrap_inner
;;;;self.run()
;;File;"/usr/local/lib/python3.7/threading.py",;line;865,;in;run
;;;;self._target(*self._args,;**self._kwargs)
;;File;"app.py",;line;48,;in;_kubernetes_job
;;;;_write_work(**kwargs)
;;File;"app.py",;line;67,;in;_write_work
;;;;simple_http_client_post.perform(gibberish_content)
;;File;"/app/models/simple_http_log_client.py",;line;12,;in;perform
;;;;return;self._simple_requests_scenario(body_json_content)
;;File;"/app/models/simple_http_log_client.py",;line;17,;in;_simple_requests_scenario
;;;;return;self.session.post(f"{self.api_url}/db",;json=body_json_content)
;;File;"/usr/local/lib/python3.7/site-packages/requests/sessions.py",;line;577,;in;post
;;;;return;self.request('POST',;url,;data=data,;json=json,;**kwargs)
;;File;"/usr/local/lib/python3.7/site-packages/requests/sessions.py",;line;529,;in;request
;;;;resp;=;self.send(prep,;**send_kwargs)
;;File;"/usr/local/lib/python3.7/site-packages/requests/sessions.py",;line;645,;in;send
;;;;r;=;adapter.send(request,;**kwargs)
;;File;"/usr/local/lib/python3.7/site-packages/requests/adapters.py",;line;519,;in;send
;;;;raise;ConnectionError(e,;request=request)
requests.exceptions.ConnectionError:;HTTPConnectionPool(host='hermes-leader',;port=8000):;Max;retries;exceeded;with;url:;/db;(Caused;by;NewConnectionError('<urllib3.connection.HTTPConnection;object;at;0x7fe8b5b65940>:;Failed;to;establish;a;new;connection:;[Errno;111];Connection;refused'))

Exception;in;thread;4:
Traceback;(most;recent;call;last):
;;File;"/usr/local/lib/python3.7/site-packages/urllib3/connection.py",;line;175,;in;_new_conn
;;;;(self._dns_host,;self.port),;self.timeout,;**extra_kw
;;File;"/usr/local/lib/python3.7/site-packages/urllib3/util/connection.py",;line;95,;in;create_connection
;;;;raise;err
;;File;"/usr/local/lib/python3.7/site-packages/urllib3/util/connection.py",;line;85,;in;create_connection
;;;;sock.connect(sa)
ConnectionRefusedError:;[Errno;111];Connection;refused

During;handling;of;the;above;exception,;another;exception;occurred:

Traceback;(most;recent;call;last):
;;File;"/usr/local/lib/python3.7/site-packages/urllib3/connectionpool.py",;line;710,;in;urlopen
;;;;chunked=chunked,
;;File;"/usr/local/lib/python3.7/site-packages/urllib3/connectionpool.py",;line;398,;in;_make_request
;;;;conn.request(method,;url,;**httplib_request_kw)
;;File;"/usr/local/lib/python3.7/site-packages/urllib3/connection.py",;line;239,;in;request
;;;;super(HTTPConnection,;self).request(method,;url,;body=body,;headers=headers)
;;File;"/usr/local/lib/python3.7/http/client.py",;line;1229,;in;request
;;;;self._send_request(method,;url,;body,;headers,;encode_chunked)
;;File;"/usr/local/lib/python3.7/http/client.py",;line;1275,;in;_send_request
;;;;self.endheaders(body,;encode_chunked=encode_chunked)
;;File;"/usr/local/lib/python3.7/http/client.py",;line;1224,;in;endheaders
;;;;self._send_output(message_body,;encode_chunked=encode_chunked)
;;File;"/usr/local/lib/python3.7/http/client.py",;line;1016,;in;_send_output
;;;;self.send(msg)
;;File;"/usr/local/lib/python3.7/http/client.py",;line;956,;in;send
;;;;self.connect()
;;File;"/usr/local/lib/python3.7/site-packages/urllib3/connection.py",;line;205,;in;connect
;;;;conn;=;self._new_conn()
;;File;"/usr/local/lib/python3.7/site-packages/urllib3/connection.py",;line;187,;in;_new_conn
;;;;self,;"Failed;to;establish;a;new;connection:;%s";%;e
urllib3.exceptions.NewConnectionError:;<urllib3.connection.HTTPConnection;object;at;0x7fe8a439f9b0>:;Failed;to;establish;a;new;connection:;[Errno;111];Connection;refused

During;handling;of;the;above;exception,;another;exception;occurred:

Traceback;(most;recent;call;last):
;;File;"/usr/local/lib/python3.7/site-packages/requests/adapters.py",;line;450,;in;send
;;;;timeout=timeout
;;File;"/usr/local/lib/python3.7/site-packages/urllib3/connectionpool.py",;line;786,;in;urlopen
;;;;method,;url,;error=e,;_pool=self,;_stacktrace=sys.exc_info()[2]
;;File;"/usr/local/lib/python3.7/site-packages/urllib3/util/retry.py",;line;592,;in;increment
;;;;raise;MaxRetryError(_pool,;url,;error;or;ResponseError(cause))
urllib3.exceptions.MaxRetryError:;HTTPConnectionPool(host='hermes-leader',;port=8000):;Max;retries;exceeded;with;url:;/db;(Caused;by;NewConnectionError('<urllib3.connection.HTTPConnection;object;at;0x7fe8a439f9b0>:;Failed;to;establish;a;new;connection:;[Errno;111];Connection;refused'))

During;handling;of;the;above;exception,;another;exception;occurred:

Traceback;(most;recent;call;last):
;;File;"/usr/local/lib/python3.7/threading.py",;line;917,;in;_bootstrap_inner
;;;;self.run()
;;File;"/usr/local/lib/python3.7/threading.py",;line;865,;in;run
;;;;self._target(*self._args,;**self._kwargs)
;;File;"app.py",;line;48,;in;_kubernetes_job
;;;;_write_work(**kwargs)
;;File;"app.py",;line;67,;in;_write_work
;;;;simple_http_client_post.perform(gibberish_content)
;;File;"/app/models/simple_http_log_client.py",;line;12,;in;perform
;;;;return;self._simple_requests_scenario(body_json_content)
;;File;"/app/models/simple_http_log_client.py",;line;17,;in;_simple_requests_scenario
;;;;return;self.session.post(f"{self.api_url}/db",;json=body_json_content)
;;File;"/usr/local/lib/python3.7/site-packages/requests/sessions.py",;line;577,;in;post
;;;;return;self.request('POST',;url,;data=data,;json=json,;**kwargs)
;;File;"/usr/local/lib/python3.7/site-packages/requests/sessions.py",;line;529,;in;request
;;;;resp;=;self.send(prep,;**send_kwargs)
;;File;"/usr/local/lib/python3.7/site-packages/requests/sessions.py",;line;645,;in;send
;;;;r;=;adapter.send(request,;**kwargs)
;;File;"/usr/local/lib/python3.7/site-packages/requests/adapters.py",;line;519,;in;send
;;;;raise;ConnectionError(e,;request=request)
requests.exceptions.ConnectionError:;HTTPConnectionPool(host='hermes-leader',;port=8000):;Max;retries;exceeded;with;url:;/db;(Caused;by;NewConnectionError('<urllib3.connection.HTTPConnection;object;at;0x7fe8a439f9b0>:;Failed;to;establish;a;new;connection:;[Errno;111];Connection;refused'))

Exception;in;thread;10:
Traceback;(most;recent;call;last):
;;File;"/usr/local/lib/python3.7/site-packages/urllib3/connectionpool.py",;line;710,;in;urlopen
;;;;chunked=chunked,
;;File;"/usr/local/lib/python3.7/site-packages/urllib3/connectionpool.py",;line;449,;in;_make_request
;;;;six.raise_from(e,;None)
;;File;"<string>",;line;3,;in;raise_from
;;File;"/usr/local/lib/python3.7/site-packages/urllib3/connectionpool.py",;line;444,;in;_make_request
;;;;httplib_response;=;conn.getresponse()
;;File;"/usr/local/lib/python3.7/http/client.py",;line;1321,;in;getresponse
;;;;response.begin()
;;File;"/usr/local/lib/python3.7/http/client.py",;line;296,;in;begin
;;;;version,;status,;reason;=;self._read_status()
;;File;"/usr/local/lib/python3.7/http/client.py",;line;265,;in;_read_status
;;;;raise;RemoteDisconnected("Remote;end;closed;connection;without"
http.client.RemoteDisconnected:;Remote;end;closed;connection;without;response

During;handling;of;the;above;exception,;another;exception;occurred:

Traceback;(most;recent;call;last):
;;File;"/usr/local/lib/python3.7/site-packages/requests/adapters.py",;line;450,;in;send
;;;;timeout=timeout
;;File;"/usr/local/lib/python3.7/site-packages/urllib3/connectionpool.py",;line;786,;in;urlopen
;;;;method,;url,;error=e,;_pool=self,;_stacktrace=sys.exc_info()[2]
;;File;"/usr/local/lib/python3.7/site-packages/urllib3/util/retry.py",;line;550,;in;increment
;;;;raise;six.reraise(type(error),;error,;_stacktrace)
;;File;"/usr/local/lib/python3.7/site-packages/urllib3/packages/six.py",;line;769,;in;reraise
;;;;raise;value.with_traceback(tb)
;;File;"/usr/local/lib/python3.7/site-packages/urllib3/connectionpool.py",;line;710,;in;urlopen
;;;;chunked=chunked,
;;File;"/usr/local/lib/python3.7/site-packages/urllib3/connectionpool.py",;line;449,;in;_make_request
;;;;six.raise_from(e,;None)
;;File;"<string>",;line;3,;in;raise_from
;;File;"/usr/local/lib/python3.7/site-packages/urllib3/connectionpool.py",;line;444,;in;_make_request
;;;;httplib_response;=;conn.getresponse()
;;File;"/usr/local/lib/python3.7/http/client.py",;line;1321,;in;getresponse
;;;;response.begin()
;;File;"/usr/local/lib/python3.7/http/client.py",;line;296,;in;begin
;;;;version,;status,;reason;=;self._read_status()
;;File;"/usr/local/lib/python3.7/http/client.py",;line;265,;in;_read_status
;;;;raise;RemoteDisconnected("Remote;end;closed;connection;without"
urllib3.exceptions.ProtocolError:;('Connection;aborted.',;RemoteDisconnected('Remote;end;closed;connection;without;response'))

During;handling;of;the;above;exception,;another;exception;occurred:

Traceback;(most;recent;call;last):
;;File;"/usr/local/lib/python3.7/threading.py",;line;917,;in;_bootstrap_inner
;;;;self.run()
;;File;"/usr/local/lib/python3.7/threading.py",;line;865,;in;run
;;;;self._target(*self._args,;**self._kwargs)
;;File;"app.py",;line;48,;in;_kubernetes_job
;;;;_write_work(**kwargs)
;;File;"app.py",;line;67,;in;_write_work
;;;;simple_http_client_post.perform(gibberish_content)
;;File;"/app/models/simple_http_log_client.py",;line;12,;in;perform
;;;;return;self._simple_requests_scenario(body_json_content)
;;File;"/app/models/simple_http_log_client.py",;line;17,;in;_simple_requests_scenario
;;;;return;self.session.post(f"{self.api_url}/db",;json=body_json_content)
;;File;"/usr/local/lib/python3.7/site-packages/requests/sessions.py",;line;577,;in;post
;;;;return;self.request('POST',;url,;data=data,;json=json,;**kwargs)
;;File;"/usr/local/lib/python3.7/site-packages/requests/sessions.py",;line;529,;in;request
;;;;resp;=;self.send(prep,;**send_kwargs)
;;File;"/usr/local/lib/python3.7/site-packages/requests/sessions.py",;line;645,;in;send
;;;;r;=;adapter.send(request,;**kwargs)
;;File;"/usr/local/lib/python3.7/site-packages/requests/adapters.py",;line;501,;in;send
;;;;raise;ConnectionError(err,;request=request)
requests.exceptions.ConnectionError:;('Connection;aborted.',;RemoteDisconnected('Remote;end;closed;connection;without;response'))

